Workbook

Sheet Instructions
A1: How to Use This Bookkeeping Dashboard
A4: 1. Open the 'Setup' tab first. Confirm your income/expense categories, tax rate, profit goals, and starting bank balance.
A5: 2. Log every transaction in the 'Transactions' tab — Date, Type (Income/Expense), Category, Description, Amount, and Tax Collected. Use the dropdowns for Type and Category; income/expense rows are color-coded automatically.
A6: 3. Check the 'Business Health Dashboard' for an at-a-glance view of cash on hand, YTD profit, margin, growth, cash runway, goal progress, top categories, and a Business Health Score.
A7: 4. The 'Monthly Dashboard', 'Quarterly Dashboard', 'Yearly Dashboard', and '5-Year Dashboard' tabs update automatically — just change the Year/Month/Quarter selector cells (yellow) at the top of each tab.
A8: 5. 'Income Breakdown' and 'Expense Breakdown' show all-time and current-year totals by category with charts and data bars.
A9: 6. 'Profit & Loss Summary' shows one row per year with year-over-year growth; 'Tax Summary' shows tax collected by month; 'Account Balance' tracks your running cash balance and reconciles against your bank statement; 'Category Trends' shows a 12-month heatmap per category.
A10: 7. Only edit yellow (input) or white cells. Green-header and formula cells update automatically — do not overwrite them.
A11: 8. To log more than 100 transactions, select the last formatted row and copy it downward; formulas will carry over.
A12: Prepared for {{CLIENT_NAME}} ({{NICHE}}). Amounts are in {{CURRENCY}}.

Sheet Setup
A1: {{CLIENT_NAME}} — Setup
A2: {{NICHE}} — configure once, everything else updates automatically
A3: Setting | B3: Value
A4: Tax Rate (%) | B4: 0.1
A5: Monthly Profit Goal ({{CURRENCY}}) | B5: 2000
A6: Annual Profit Goal ({{CURRENCY}}) | B6: =B5*12 -> 24000
A7: Starting Bank Balance ({{CURRENCY}}) | B7: 0
A8: Income Categories | B8: Expense Categories | C8: All Categories (Transactions dropdown)
A9: Sales Revenue | B9: Cost of Goods | C9: Sales Revenue
A10: Shipping Income | B10: Shipping Costs | C10: Shipping Income
A11: Custom Orders | B11: Marketing | C11: Custom Orders
A12: Wholesale | B12: Software & Tools | C12: Wholesale
A13: Other Income | B13: Fees & Commissions | C13: Other Income
B14: Office Supplies | C14: Cost of Goods
B15: Rent | C15: Shipping Costs
B16: Utilities | C16: Marketing
B17: Other Expense | C17: Software & Tools
C18: Fees & Commissions
C19: Office Supplies
C20: Rent
C21: Utilities
C22: Other Expense

Sheet Transactions
A1: {{CLIENT_NAME}} — Transactions
A2: Date | B2: Type | C2: Category | D2: Description | E2: Amount ({{CURRENCY}}) | F2: Tax Collected ({{CURRENCY}}) | G2: Year | H2: Month
G3: =IFERROR(YEAR(A3),"") -> 1899 | H3: =IFERROR(MONTH(A3),"") -> 12
G4: =IFERROR(YEAR(A4),"") -> 1899 | H4: =IFERROR(MONTH(A4),"") -> 12
G5: =IFERROR(YEAR(A5),"") -> 1899 | H5: =IFERROR(MONTH(A5),"") -> 12
G6: =IFERROR(YEAR(A6),"") -> 1899 | H6: =IFERROR(MONTH(A6),"") -> 12
G7: =IFERROR(YEAR(A7),"") -> 1899 | H7: =IFERROR(MONTH(A7),"") -> 12
G8: =IFERROR(YEAR(A8),"") -> 1899 | H8: =IFERROR(MONTH(A8),"") -> 12
G9: =IFERROR(YEAR(A9),"") -> 1899 | H9: =IFERROR(MONTH(A9),"") -> 12
G10: =IFERROR(YEAR(A10),"") -> 1899 | H10: =IFERROR(MONTH(A10),"") -> 12
G11: =IFERROR(YEAR(A11),"") -> 1899 | H11: =IFERROR(MONTH(A11),"") -> 12
G12: =IFERROR(YEAR(A12),"") -> 1899 | H12: =IFERROR(MONTH(A12),"") -> 12
G13: =IFERROR(YEAR(A13),"") -> 1899 | H13: =IFERROR(MONTH(A13),"") -> 12
G14: =IFERROR(YEAR(A14),"") -> 1899 | H14: =IFERROR(MONTH(A14),"") -> 12
... G102: =IFERROR(YEAR(A102),"") -> 1899 | H102: =IFERROR(MONTH(A102),"") -> 12

Sheet Business Health Dashboard
A1: {{CLIENT_NAME}} — Business Health Dashboard
A2: {{NICHE}} — your business at a glance, figures in {{CURRENCY}}
A3: Year | B3: 2026
A5: Cash on Hand ({{CURRENCY}}) | B5: YTD Net Profit ({{CURRENCY}}) | C5: Profit Margin (YTD) | D5: YoY Income Growth | E5: Cash Runway (Months)
A6: ='Account Balance'!B4 -> 0 | B6: =SUMIFS(Transactions!$E$3:$E$102,Transactions!$B$3:$B$102,"Income",Transactions!$G$3:$G$102,$B$3)-SUMIFS(Transactions!$E$3:$E$102,Transactions!$B$3:$B$102,"Expense",Transactions!$G$3:$G$102,$B$3) -> 0 | C6: =IFERROR(B6/SUMIFS(Transactions!$E$3:$E$102,Transactions!$B$3:$B$102,"Income",Transactions!$G$3:$G$102,$B$3),0) -> 0 | D6: =IFERROR((SUMIFS(Transactions!$E$3:$E$102,Transactions!$B$3:$B$102,"Income",Transactions!$G$3:$G$102,$B$3)-SUMIFS(Transactions!$E$3:$E$102,Transactions!$B$3:$B$102,"Income",Transactions!$G$3:$G$102,$B$3-1))/SUMIFS(Transactions!$E$3:$E$102,Transactions!$B$3:$B$102,"Income",Transactions!$G$3:$G$102,$B$3-1),0) -> 0 | E6: =IFERROR(A6/(SUMIFS(Transactions!$E$3:$E$102,Transactions!$B$3:$B$102,"Expense",Transactions!$G$3:$G$102,$B$3)/12),0) -> 0
A9: Goal Progress — YTD Net Profit vs Annual Goal
A10: Progress | B10: =IFERROR(B6/Setup!$B$6,0) -> 0
A12: Top Category This Year
B13: Category | C13: Amount ({{CURRENCY}})
A14: Top Income | B14: =INDEX('Income Breakdown'!A6:A10,MATCH(MAX('Income Breakdown'!C6:C10),'Income Breakdown'!C6:C10,0)) -> Sales Revenue | C14: =MAX('Income Breakdown'!C6:C10) -> 0
A15: Top Expense | B15: =INDEX('Expense Breakdown'!A6:A14,MATCH(MAX('Expense Breakdown'!C6:C14),'Expense Breakdown'!C6:C14,0)) -> Cost of Goods | C15: =MAX('Expense Breakdown'!C6:C14) -> 0
A18: Business Health Score
A19: Margin Score (30%+ margin = 100) | B19: =MIN(MAX(C6/0.3,0),1)*100 -> 0
A20: Growth Score (-20% to +20% mapped to 0-100) | B20: =MIN(MAX((D6+0.2)/0.4,0),1)*100 -> 50
A21: Runway Score (6+ months = 100) | B21: =MIN(MAX(E6/6,0),1)*100 -> 0
A22: Overall Health Score (0-100) | B22: =AVERAGE(B19:B21) -> 16.666667
A24: Methodology: each sub-score is a simple linear scale between the thresholds shown (e.g. Margin Score reaches 100 once Profit Margin hits 30%). This is a rule-of-thumb indicator, not professional financial advice.

Sheet Monthly Dashboard
A1: {{CLIENT_NAME}} — Monthly Dashboard
A2: {{NICHE}} — figures in {{CURRENCY}}
A3: Year | B3: 2026 | C3: Month | D3: 1
A5: Total Income ({{CURRENCY}}) | B5: Total Expenses ({{CURRENCY}}) | C5: Net Profit ({{CURRENCY}}) | D5: Profit Margin | E5: Tax Collected ({{CURRENCY}})
A6: =SUMIFS(Transactions!$E$3:$E$102,Transactions!$B$3:$B$102,"Income",Transactions!$G$3:$G$102,$B$3,Transactions!$H$3:$H$102,$D$3) -> 0 | B6: =SUMIFS(Transactions!$E$3:$E$102,Transactions!$B$3:$B$102,"Expense",Transactions!$G$3:$G$102,$B$3,Transactions!$H$3:$H$102,$D$3) -> 0 | C6: =A6-B6 -> 0 | D6: =IFERROR(C6/A6,0) -> 0 | E6: =SUMIFS(Transactions!$F$3:$F$102,Transactions!$G$3:$G$102,$B$3,Transactions!$H$3:$H$102,$D$3) -> 0
A9: Income by Category | D9: Expenses by Category
A10: Category | B10: Amount | D10: Category | E10: Amount
A11: Sales Revenue | B11: =SUMIFS(Transactions!$E$3:$E$102,Transactions!$B$3:$B$102,"Income",Transactions!$C$3:$C$102,"Sales Revenue",Transactions!$G$3:$G$102,$B$3,Transactions!$H$3:$H$102,$D$3) -> 0 | D11: Cost of Goods | E11: =SUMIFS(Transactions!$E$3:$E$102,Transactions!$B$3:$B$102,"Expense",Transactions!$C$3:$C$102,"Cost of Goods",Transactions!$G$3:$G$102,$B$3,Transactions!$H$3:$H$102,$D$3) -> 0
A12: Shipping Income | B12: =SUMIFS(Transactions!$E$3:$E$102,Transactions!$B$3:$B$102,"Income",Transactions!$C$3:$C$102,"Shipping Income",Transactions!$G$3:$G$102,$B$3,Transactions!$H$3:$H$102,$D$3) -> 0 | D12: Shipping Costs | E12: =SUMIFS(Transactions!$E$3:$E$102,Transactions!$B$3:$B$102,"Expense",Transactions!$C$3:$C$102,"Shipping Costs",Transactions!$G$3:$G$102,$B$3,Transactions!$H$3:$H$102,$D$3) -> 0
A13: Custom Orders | B13: =SUMIFS(Transactions!$E$3:$E$102,Transactions!$B$3:$B$102,"Income",Transactions!$C$3:$C$102,"Custom Orders",Transactions!$G$3:$G$102,$B$3,Transactions!$H$3:$H$102,$D$3) -> 0 | D13: Marketing | E13: =SUMIFS(Transactions!$E$3:$E$102,Transactions!$B$3:$B$102,"Expense",Transactions!$C$3:$C$102,"Marketing",Transactions!$G$3:$G$102,$B$3,Transactions!$H$3:$H$102,$D$3) -> 0
A14: Wholesale | B14: =SUMIFS(Transactions!$E$3:$E$102,Transactions!$B$3:$B$102,"Income",Transactions!$C$3:$C$102,"Wholesale",Transactions!$G$3:$G$102,$B$3,Transactions!$H$3:$H$102,$D$3) -> 0 | D14: Software & Tools | E14: =SUMIFS(Transactions!$E$3:$E$102,Transactions!$B$3:$B$102,"Expense",Transactions!$C$3:$C$102,"Software & Tools",Transactions!$G$3:$G$102,$B$3,Transactions!$H$3:$H$102,$D$3) -> 0
A15: Other Income | B15: =SUMIFS(Transactions!$E$3:$E$102,Transactions!$B$3:$B$102,"Income",Transactions!$C$3:$C$102,"Other Income",Transactions!$G$3:$G$102,$B$3,Transactions!$H$3:$H$102,$D$3) -> 0 | D15: Fees & Commissions | E15: =SUMIFS(Transactions!$E$3:$E$102,Transactions!$B$3:$B$102,"Expense",Transactions!$C$3:$C$102,"Fees & Commissions",Transactions!$G$3:$G$102,$B$3,Transactions!$H$3:$H$102,$D$3) -> 0
D16: Office Supplies | E16: =SUMIFS(Transactions!$E$3:$E$102,Transactions!$B$3:$B$102,"Expense",Transactions!$C$3:$C$102,"Office Supplies",Transactions!$G$3:$G$102,$B$3,Transactions!$H$3:$H$102,$D$3) -> 0
D17: Rent | E17: =SUMIFS(Transactions!$E$3:$E$102,Transactions!$B$3:$B$102,"Expense",Transactions!$C$3:$C$102,"Rent",Transactions!$G$3:$G$102,$B$3,Transactions!$H$3:$H$102,$D$3) -> 0
D18: Utilities | E18: =SUMIFS(Transactions!$E$3:$E$102,Transactions!$B$3:$B$102,"Expense",Transactions!$C$3:$C$102,"Utilities",Transactions!$G$3:$G$102,$B$3,Transactions!$H$3:$H$102,$D$3) -> 0
D19: Other Expense | E19: =SUMIFS(Transactions!$E$3:$E$102,Transactions!$B$3:$B$102,"Expense",Transactions!$C$3:$C$102,"Other Expense",Transactions!$G$3:$G$102,$B$3,Transactions!$H$3:$H$102,$D$3) -> 0
A24: Income vs Expenses
A25: Metric | B25: Amount
A26: Income | B26: =A6 -> 0
A27: Expenses | B27: =B6 -> 0

Sheet Quarterly Dashboard
A1: {{CLIENT_NAME}} — Quarterly Dashboard
A2: {{NICHE}} — figures in {{CURRENCY}}
A3: Year | B3: 2026 | C3: Quarter | D3: 1
A5: Total Income ({{CURRENCY}}) | B5: Total Expenses ({{CURRENCY}}) | C5: Net Profit ({{CURRENCY}}) | D5: Profit Margin | E5: Tax Collected ({{CURRENCY}})
A6: =SUMIFS(Transactions!$E$3:$E$102,Transactions!$B$3:$B$102,"Income",Transactions!$G$3:$G$102,$B$3,Transactions!$H$3:$H$102,">="&(($D$3-1)*3+1),Transactions!$H$3:$H$102,"<="&((($D$3-1)*3+1)+2)) -> 0 | B6: =SUMIFS(Transactions!$E$3:$E$102,Transactions!$B$3:$B$102,"Expense",Transactions!$G$3:$G$102,$B$3,Transactions!$H$3:$H$102,">="&(($D$3-1)*3+1),Transactions!$H$3:$H$102,"<="&((($D$3-1)*3+1)+2)) -> 0 | C6: =A6-B6 -> 0 | D6: =IFERROR(C6/A6,0) -> 0 | E6: =SUMIFS(Transactions!$F$3:$F$102,Transactions!$G$3:$G$102,$B$3,Transactions!$H$3:$H$102,">="&(($D$3-1)*3+1),Transactions!$H$3:$H$102,"<="&((($D$3-1)*3+1)+2)) -> 0
A9: Net Profit by Quarter — Selected Year
A10: Quarter | B10: Income | C10: Expenses | D10: Net Profit
A11: Q1 | B11: =SUMIFS(Transactions!$E$3:$E$102,Transactions!$B$3:$B$102,"Income",Transactions!$G$3:$G$102,$B$3,Transactions!$H$3:$H$102,">="&((1-1)*3+1),Transactions!$H$3:$H$102,"<="&(((1-1)*3+1)+2)) -> 0 | C11: =SUMIFS(Transactions!$E$3:$E$102,Transactions!$B$3:$B$102,"Expense",Transactions!$G$3:$G$102,$B$3,Transactions!$H$3:$H$102,">="&((1-1)*3+1),Transactions!$H$3:$H$102,"<="&(((1-1)*3+1)+2)) -> 0 | D11: =B11-C11 -> 0
A12: Q2 | B12: =SUMIFS(Transactions!$E$3:$E$102,Transactions!$B$3:$B$102,"Income",Transactions!$G$3:$G$102,$B$3,Transactions!$H$3:$H$102,">="&((2-1)*3+1),Transactions!$H$3:$H$102,"<="&(((2-1)*3+1)+2)) -> 0 | C12: =SUMIFS(Transactions!$E$3:$E$102,Transactions!$B$3:$B$102,"Expense",Transactions!$G$3:$G$102,$B$3,Transactions!$H$3:$H$102,">="&((2-1)*3+1),Transactions!$H$3:$H$102,"<="&(((2-1)*3+1)+2)) -> 0 | D12: =B12-C12 -> 0
A13: Q3 | B13: =SUMIFS(Transactions!$E$3:$E$102,Transactions!$B$3:$B$102,"Income",Transactions!$G$3:$G$102,$B$3,Transactions!$H$3:$H$102,">="&((3-1)*3+1),Transactions!$H$3:$H$102,"<="&(((3-1)*3+1)+2)) -> 0 | C13: =SUMIFS(Transactions!$E$3:$E$102,Transactions!$B$3:$B$102,"Expense",Transactions!$G$3:$G$102,$B$3,Transactions!$H$3:$H$102,">="&((3-1)*3+1),Transactions!$H$3:$H$102,"<="&(((3-1)*3+1)+2)) -> 0 | D13: =B13-C13 -> 0
A14: Q4 | B14: =SUMIFS(Transactions!$E$3:$E$102,Transactions!$B$3:$B$102,"Income",Transactions!$G$3:$G$102,$B$3,Transactions!$H$3:$H$102,">="&((4-1)*3+1),Transactions!$H$3:$H$102,"<="&(((4-1)*3+1)+2)) -> 0 | C14: =SUMIFS(Transactions!$E$3:$E$102,Transactions!$B$3:$B$102,"Expense",Transactions!$G$3:$G$102,$B$3,Transactions!$H$3:$H$102,">="&((4-1)*3+1),Transactions!$H$3:$H$102,"<="&(((4-1)*3+1)+2)) -> 0 | D14: =B14-C14 -> 0

Sheet Yearly Dashboard
A1: {{CLIENT_NAME}} — Yearly Dashboard
A2: {{NICHE}} — figures in {{CURRENCY}}
A3: Year | B3: 2026
A5: Total Income ({{CURRENCY}}) | B5: Total Expenses ({{CURRENCY}}) | C5: Net Profit ({{CURRENCY}}) | D5: Profit Margin | E5: Tax Collected ({{CURRENCY}})
A6: =SUMIFS(Transactions!$E$3:$E$102,Transactions!$B$3:$B$102,"Income",Transactions!$G$3:$G$102,$B$3) -> 0 | B6: =SUMIFS(Transactions!$E$3:$E$102,Transactions!$B$3:$B$102,"Expense",Transactions!$G$3:$G$102,$B$3) -> 0 | C6: =A6-B6 -> 0 | D6: =IFERROR(C6/A6,0) -> 0 | E6: =SUMIFS(Transactions!$F$3:$F$102,Transactions!$G$3:$G$102,$B$3) -> 0
A9: Monthly Breakdown — Selected Year
A10: Month | B10: Income | C10: Expenses | D10: Net Profit | E10: Goal | F10: vs Goal
A11: Jan | B11: =SUMIFS(Transactions!$E$3:$E$102,Transactions!$B$3:$B$102,"Income",Transactions!$G$3:$G$102,$B$3,Transactions!$H$3:$H$102,1) -> 0 | C11: =SUMIFS(Transactions!$E$3:$E$102,Transactions!$B$3:$B$102,"Expense",Transactions!$G$3:$G$102,$B$3,Transactions!$H$3:$H$102,1) -> 0 | D11: =B11-C11 -> 0 | E11: =Setup!$B$5 -> 2000 | F11: =D11-E11 -> -2000
A12: Feb | B12: =SUMIFS(Transactions!$E$3:$E$102,Transactions!$B$3:$B$102,"Income",Transactions!$G$3:$G$102,$B$3,Transactions!$H$3:$H$102,2) -> 0 | C12: =SUMIFS(Transactions!$E$3:$E$102,Transactions!$B$3:$B$102,"Expense",Transactions!$G$3:$G$102,$B$3,Transactions!$H$3:$H$102,2) -> 0 | D12: =B12-C12 -> 0 | E12: =Setup!$B$5 -> 2000 | F12: =D12-E12 -> -2000
A13: Mar | B13: =SUMIFS(Transactions!$E$3:$E$102,Transactions!$B$3:$B$102,"Income",Transactions!$G$3:$G$102,$B$3,Transactions!$H$3:$H$102,3) -> 0 | C13: =SUMIFS(Transactions!$E$3:$E$102,Transactions!$B$3:$B$102,"Expense",Transactions!$G$3:$G$102,$B$3,Transactions!$H$3:$H$102,3) -> 0 | D13: =B13-C13 -> 0 | E13: =Setup!$B$5 -> 2000 | F13: =D13-E13 -> -2000
A14: Apr | B14: =SUMIFS(Transactions!$E$3:$E$102,Transactions!$B$3:$B$102,"Income",Transactions!$G$3:$G$102,$B$3,Transactions!$H$3:$H$102,4) -> 0 | C14: =SUMIFS(Transactions!$E$3:$E$102,Transactions!$B$3:$B$102,"Expense",Transactions!$G$3:$G$102,$B$3,Transactions!$H$3:$H$102,4) -> 0 | D14: =B14-C14 -> 0 | E14: =Setup!$B$5 -> 2000 | F14: =D14-E14 -> -2000
A15: May | B15: =SUMIFS(Transactions!$E$3:$E$102,Transactions!$B$3:$B$102,"Income",Transactions!$G$3:$G$102,$B$3,Transactions!$H$3:$H$102,5) -> 0 | C15: =SUMIFS(Transactions!$E$3:$E$102,Transactions!$B$3:$B$102,"Expense",Transactions!$G$3:$G$102,$B$3,Transactions!$H$3:$H$102,5) -> 0 | D15: =B15-C15 -> 0 | E15: =Setup!$B$5 -> 2000 | F15: =D15-E15 -> -2000
A16: Jun | B16: =SUMIFS(Transactions!$E$3:$E$102,Transactions!$B$3:$B$102,"Income",Transactions!$G$3:$G$102,$B$3,Transactions!$H$3:$H$102,6) -> 0 | C16: =SUMIFS(Transactions!$E$3:$E$102,Transactions!$B$3:$B$102,"Expense",Transactions!$G$3:$G$102,$B$3,Transactions!$H$3:$H$102,6) -> 0 | D16: =B16-C16 -> 0 | E16: =Setup!$B$5 -> 2000 | F16: =D16-E16 -> -2000
A17: Jul | B17: =SUMIFS(Transactions!$E$3:$E$102,Transactions!$B$3:$B$102,"Income",Transactions!$G$3:$G$102,$B$3,Transactions!$H$3:$H$102,7) -> 0 | C17: =SUMIFS(Transactions!$E$3:$E$102,Transactions!$B$3:$B$102,"Expense",Transactions!$G$3:$G$102,$B$3,Transactions!$H$3:$H$102,7) -> 0 | D17: =B17-C17 -> 0 | E17: =Setup!$B$5 -> 2000 | F17: =D17-E17 -> -2000
A18: Aug | B18: =SUMIFS(Transactions!$E$3:$E$102,Transactions!$B$3:$B$102,"Income",Transactions!$G$3:$G$102,$B$3,Transactions!$H$3:$H$102,8) -> 0 | C18: =SUMIFS(Transactions!$E$3:$E$102,Transactions!$B$3:$B$102,"Expense",Transactions!$G$3:$G$102,$B$3,Transactions!$H$3:$H$102,8) -> 0 | D18: =B18-C18 -> 0 | E18: =Setup!$B$5 -> 2000 | F18: =D18-E18 -> -2000
A19: Sep | B19: =SUMIFS(Transactions!$E$3:$E$102,Transactions!$B$3:$B$102,"Income",Transactions!$G$3:$G$102,$B$3,Transactions!$H$3:$H$102,9) -> 0 | C19: =SUMIFS(Transactions!$E$3:$E$102,Transactions!$B$3:$B$102,"Expense",Transactions!$G$3:$G$102,$B$3,Transactions!$H$3:$H$102,9) -> 0 | D19: =B19-C19 -> 0 | E19: =Setup!$B$5 -> 2000 | F19: =D19-E19 -> -2000
A20: Oct | B20: =SUMIFS(Transactions!$E$3:$E$102,Transactions!$B$3:$B$102,"Income",Transactions!$G$3:$G$102,$B$3,Transactions!$H$3:$H$102,10) -> 0 | C20: =SUMIFS(Transactions!$E$3:$E$102,Transactions!$B$3:$B$102,"Expense",Transactions!$G$3:$G$102,$B$3,Transactions!$H$3:$H$102,10) -> 0 | D20: =B20-C20 -> 0 | E20: =Setup!$B$5 -> 2000 | F20: =D20-E20 -> -2000
A21: Nov | B21: =SUMIFS(Transactions!$E$3:$E$102,Transactions!$B$3:$B$102,"Income",Transactions!$G$3:$G$102,$B$3,Transactions!$H$3:$H$102,11) -> 0 | C21: =SUMIFS(Transactions!$E$3:$E$102,Transactions!$B$3:$B$102,"Expense",Transactions!$G$3:$G$102,$B$3,Transactions!$H$3:$H$102,11) -> 0 | D21: =B21-C21 -> 0 | E21: =Setup!$B$5 -> 2000 | F21: =D21-E21 -> -2000
A22: Dec | B22: =SUMIFS(Transactions!$E$3:$E$102,Transactions!$B$3:$B$102,"Income",Transactions!$G$3:$G$102,$B$3,Transactions!$H$3:$H$102,12) -> 0 | C22: =SUMIFS(Transactions!$E$3:$E$102,Transactions!$B$3:$B$102,"Expense",Transactions!$G$3:$G$102,$B$3,Transactions!$H$3:$H$102,12) -> 0 | D22: =B22-C22 -> 0 | E22: =Setup!$B$5 -> 2000 | F22: =D22-E22 -> -2000

Sheet 5-Year Dashboard
A1: {{CLIENT_NAME}} — 5-Year Dashboard
A2: {{NICHE}} — figures in {{CURRENCY}}
A3: Uses the first 5 years listed in 'Profit & Loss Summary' (set Start Year there).
A5: Year | B5: Income | C5: Expenses | D5: Net Profit
A6: ='Profit & Loss Summary'!A6 -> 2024 | B6: ='Profit & Loss Summary'!B6 -> 0 | C6: ='Profit & Loss Summary'!C6 -> 0 | D6: ='Profit & Loss Summary'!D6 -> 0
A7: ='Profit & Loss Summary'!A7 -> 2025 | B7: ='Profit & Loss Summary'!B7 -> 0 | C7: ='Profit & Loss Summary'!C7 -> 0 | D7: ='Profit & Loss Summary'!D7 -> 0
A8: ='Profit & Loss Summary'!A8 -> 2026 | B8: ='Profit & Loss Summary'!B8 -> 0 | C8: ='Profit & Loss Summary'!C8 -> 0 | D8: ='Profit & Loss Summary'!D8 -> 0
A9: ='Profit & Loss Summary'!A9 -> 2027 | B9: ='Profit & Loss Summary'!B9 -> 0 | C9: ='Profit & Loss Summary'!C9 -> 0 | D9: ='Profit & Loss Summary'!D9 -> 0
A10: ='Profit & Loss Summary'!A10 -> 2028 | B10: ='Profit & Loss Summary'!B10 -> 0 | C10: ='Profit & Loss Summary'!C10 -> 0 | D10: ='Profit & Loss Summary'!D10 -> 0
A12: 5-Year Totals
A13: Total Income ({{CURRENCY}}) | B13: Total Expenses ({{CURRENCY}}) | C13: Total Net Profit ({{CURRENCY}}) | D13: Avg Annual Profit ({{CURRENCY}})
A14: =SUM(B6:B10) -> 0 | B14: =SUM(C6:C10) -> 0 | C14: =SUM(D6:D10) -> 0 | D14: =AVERAGE(D6:D10) -> 0

Sheet Income Breakdown
A1: {{CLIENT_NAME}} — Income Breakdown
A2: {{NICHE}} — figures in {{CURRENCY}}
A3: Current Year | B3: 2026
A5: Category | B5: All-Time Total | C5: Current Year Total
A6: Sales Revenue | B6: =SUMIFS(Transactions!$E$3:$E$102,Transactions!$B$3:$B$102,"Income",Transactions!$C$3:$C$102,"Sales Revenue") -> 0 | C6: =SUMIFS(Transactions!$E$3:$E$102,Transactions!$B$3:$B$102,"Income",Transactions!$C$3:$C$102,"Sales Revenue",Transactions!$G$3:$G$102,$B$3) -> 0
A7: Shipping Income | B7: =SUMIFS(Transactions!$E$3:$E$102,Transactions!$B$3:$B$102,"Income",Transactions!$C$3:$C$102,"Shipping Income") -> 0 | C7: =SUMIFS(Transactions!$E$3:$E$102,Transactions!$B$3:$B$102,"Income",Transactions!$C$3:$C$102,"Shipping Income",Transactions!$G$3:$G$102,$B$3) -> 0
A8: Custom Orders | B8: =SUMIFS(Transactions!$E$3:$E$102,Transactions!$B$3:$B$102,"Income",Transactions!$C$3:$C$102,"Custom Orders") -> 0 | C8: =SUMIFS(Transactions!$E$3:$E$102,Transactions!$B$3:$B$102,"Income",Transactions!$C$3:$C$102,"Custom Orders",Transactions!$G$3:$G$102,$B$3) -> 0
A9: Wholesale | B9: =SUMIFS(Transactions!$E$3:$E$102,Transactions!$B$3:$B$102,"Income",Transactions!$C$3:$C$102,"Wholesale") -> 0 | C9: =SUMIFS(Transactions!$E$3:$E$102,Transactions!$B$3:$B$102,"Income",Transactions!$C$3:$C$102,"Wholesale",Transactions!$G$3:$G$102,$B$3) -> 0
A10: Other Income | B10: =SUMIFS(Transactions!$E$3:$E$102,Transactions!$B$3:$B$102,"Income",Transactions!$C$3:$C$102,"Other Income") -> 0 | C10: =SUMIFS(Transactions!$E$3:$E$102,Transactions!$B$3:$B$102,"Income",Transactions!$C$3:$C$102,"Other Income",Transactions!$G$3:$G$102,$B$3) -> 0

Sheet Expense Breakdown
A1: {{CLIENT_NAME}} — Expense Breakdown
A2: {{NICHE}} — figures in {{CURRENCY}}
A3: Current Year | B3: 2026
A5: Category | B5: All-Time Total | C5: Current Year Total
A6: Cost of Goods | B6: =SUMIFS(Transactions!$E$3:$E$102,Transactions!$B$3:$B$102,"Expense",Transactions!$C$3:$C$102,"Cost of Goods") -> 0 | C6: =SUMIFS(Transactions!$E$3:$E$102,Transactions!$B$3:$B$102,"Expense",Transactions!$C$3:$C$102,"Cost of Goods",Transactions!$G$3:$G$102,$B$3) -> 0
A7: Shipping Costs | B7: =SUMIFS(Transactions!$E$3:$E$102,Transactions!$B$3:$B$102,"Expense",Transactions!$C$3:$C$102,"Shipping Costs") -> 0 | C7: =SUMIFS(Transactions!$E$3:$E$102,Transactions!$B$3:$B$102,"Expense",Transactions!$C$3:$C$102,"Shipping Costs",Transactions!$G$3:$G$102,$B$3) -> 0
A8: Marketing | B8: =SUMIFS(Transactions!$E$3:$E$102,Transactions!$B$3:$B$102,"Expense",Transactions!$C$3:$C$102,"Marketing") -> 0 | C8: =SUMIFS(Transactions!$E$3:$E$102,Transactions!$B$3:$B$102,"Expense",Transactions!$C$3:$C$102,"Marketing",Transactions!$G$3:$G$102,$B$3) -> 0
A9: Software & Tools | B9: =SUMIFS(Transactions!$E$3:$E$102,Transactions!$B$3:$B$102,"Expense",Transactions!$C$3:$C$102,"Software & Tools") -> 0 | C9: =SUMIFS(Transactions!$E$3:$E$102,Transactions!$B$3:$B$102,"Expense",Transactions!$C$3:$C$102,"Software & Tools",Transactions!$G$3:$G$102,$B$3) -> 0
A10: Fees & Commissions | B10: =SUMIFS(Transactions!$E$3:$E$102,Transactions!$B$3:$B$102,"Expense",Transactions!$C$3:$C$102,"Fees & Commissions") -> 0 | C10: =SUMIFS(Transactions!$E$3:$E$102,Transactions!$B$3:$B$102,"Expense",Transactions!$C$3:$C$102,"Fees & Commissions",Transactions!$G$3:$G$102,$B$3) -> 0
A11: Office Supplies | B11: =SUMIFS(Transactions!$E$3:$E$102,Transactions!$B$3:$B$102,"Expense",Transactions!$C$3:$C$102,"Office Supplies") -> 0 | C11: =SUMIFS(Transactions!$E$3:$E$102,Transactions!$B$3:$B$102,"Expense",Transactions!$C$3:$C$102,"Office Supplies",Transactions!$G$3:$G$102,$B$3) -> 0
A12: Rent | B12: =SUMIFS(Transactions!$E$3:$E$102,Transactions!$B$3:$B$102,"Expense",Transactions!$C$3:$C$102,"Rent") -> 0 | C12: =SUMIFS(Transactions!$E$3:$E$102,Transactions!$B$3:$B$102,"Expense",Transactions!$C$3:$C$102,"Rent",Transactions!$G$3:$G$102,$B$3) -> 0
A13: Utilities | B13: =SUMIFS(Transactions!$E$3:$E$102,Transactions!$B$3:$B$102,"Expense",Transactions!$C$3:$C$102,"Utilities") -> 0 | C13: =SUMIFS(Transactions!$E$3:$E$102,Transactions!$B$3:$B$102,"Expense",Transactions!$C$3:$C$102,"Utilities",Transactions!$G$3:$G$102,$B$3) -> 0
A14: Other Expense | B14: =SUMIFS(Transactions!$E$3:$E$102,Transactions!$B$3:$B$102,"Expense",Transactions!$C$3:$C$102,"Other Expense") -> 0 | C14: =SUMIFS(Transactions!$E$3:$E$102,Transactions!$B$3:$B$102,"Expense",Transactions!$C$3:$C$102,"Other Expense",Transactions!$G$3:$G$102,$B$3) -> 0

Sheet Profit & Loss Summary
A1: {{CLIENT_NAME}} — Profit & Loss Summary
A2: {{NICHE}} — one row per year, figures in {{CURRENCY}}
A3: Start Year | B3: 2024 | C3: (table below lists this year and the next 9 years)
A5: Year | B5: Income | C5: Expenses | D5: Net Profit | E5: Profit Margin | F5: Tax Collected | G5: YoY Income Growth
A6: =$B$3 -> 2024 | B6: =SUMIFS(Transactions!$E$3:$E$102,Transactions!$B$3:$B$102,"Income",Transactions!$G$3:$G$102,A6) -> 0 | C6: =SUMIFS(Transactions!$E$3:$E$102,Transactions!$B$3:$B$102,"Expense",Transactions!$G$3:$G$102,A6) -> 0 | D6: =B6-C6 -> 0 | E6: =IFERROR(D6/B6,0) -> 0 | F6: =SUMIFS(Transactions!$F$3:$F$102,Transactions!$G$3:$G$102,A6) -> 0 | G6: ="n/a" -> n/a
A7: =A6+1 -> 2025 | B7: =SUMIFS(Transactions!$E$3:$E$102,Transactions!$B$3:$B$102,"Income",Transactions!$G$3:$G$102,A7) -> 0 | C7: =SUMIFS(Transactions!$E$3:$E$102,Transactions!$B$3:$B$102,"Expense",Transactions!$G$3:$G$102,A7) -> 0 | D7: =B7-C7 -> 0 | E7: =IFERROR(D7/B7,0) -> 0 | F7: =SUMIFS(Transactions!$F$3:$F$102,Transactions!$G$3:$G$102,A7) -> 0 | G7: =IFERROR((B7-B6)/B6,0) -> 0
A8: =A7+1 -> 2026 | B8: =SUMIFS(Transactions!$E$3:$E$102,Transactions!$B$3:$B$102,"Income",Transactions!$G$3:$G$102,A8) -> 0 | C8: =SUMIFS(Transactions!$E$3:$E$102,Transactions!$B$3:$B$102,"Expense",Transactions!$G$3:$G$102,A8) -> 0 | D8: =B8-C8 -> 0 | E8: =IFERROR(D8/B8,0) -> 0 | F8: =SUMIFS(Transactions!$F$3:$F$102,Transactions!$G$3:$G$102,A8) -> 0 | G8: =IFERROR((B8-B7)/B7,0) -> 0
A9: =A8+1 -> 2027 | B9: =SUMIFS(Transactions!$E$3:$E$102,Transactions!$B$3:$B$102,"Income",Transactions!$G$3:$G$102,A9) -> 0 | C9: =SUMIFS(Transactions!$E$3:$E$102,Transactions!$B$3:$B$102,"Expense",Transactions!$G$3:$G$102,A9) -> 0 | D9: =B9-C9 -> 0 | E9: =IFERROR(D9/B9,0) -> 0 | F9: =SUMIFS(Transactions!$F$3:$F$102,Transactions!$G$3:$G$102,A9) -> 0 | G9: =IFERROR((B9-B8)/B8,0) -> 0
A10: =A9+1 -> 2028 | B10: =SUMIFS(Transactions!$E$3:$E$102,Transactions!$B$3:$B$102,"Income",Transactions!$G$3:$G$102,A10) -> 0 | C10: =SUMIFS(Transactions!$E$3:$E$102,Transactions!$B$3:$B$102,"Expense",Transactions!$G$3:$G$102,A10) -> 0 | D10: =B10-C10 -> 0 | E10: =IFERROR(D10/B10,0) -> 0 | F10: =SUMIFS(Transactions!$F$3:$F$102,Transactions!$G$3:$G$102,A10) -> 0 | G10: =IFERROR((B10-B9)/B9,0) -> 0
A11: =A10+1 -> 2029 | B11: =SUMIFS(Transactions!$E$3:$E$102,Transactions!$B$3:$B$102,"Income",Transactions!$G$3:$G$102,A11) -> 0 | C11: =SUMIFS(Transactions!$E$3:$E$102,Transactions!$B$3:$B$102,"Expense",Transactions!$G$3:$G$102,A11) -> 0 | D11: =B11-C11 -> 0 | E11: =IFERROR(D11/B11,0) -> 0 | F11: =SUMIFS(Transactions!$F$3:$F$102,Transactions!$G$3:$G$102,A11) -> 0 | G11: =IFERROR((B11-B10)/B10,0) -> 0
A12: =A11+1 -> 2030 | B12: =SUMIFS(Transactions!$E$3:$E$102,Transactions!$B$3:$B$102,"Income",Transactions!$G$3:$G$102,A12) -> 0 | C12: =SUMIFS(Transactions!$E$3:$E$102,Transactions!$B$3:$B$102,"Expense",Transactions!$G$3:$G$102,A12) -> 0 | D12: =B12-C12 -> 0 | E12: =IFERROR(D12/B12,0) -> 0 | F12: =SUMIFS(Transactions!$F$3:$F$102,Transactions!$G$3:$G$102,A12) -> 0 | G12: =IFERROR((B12-B11)/B11,0) -> 0
A13: =A12+1 -> 2031 | B13: =SUMIFS(Transactions!$E$3:$E$102,Transactions!$B$3:$B$102,"Income",Transactions!$G$3:$G$102,A13) -> 0 | C13: =SUMIFS(Transactions!$E$3:$E$102,Transactions!$B$3:$B$102,"Expense",Transactions!$G$3:$G$102,A13) -> 0 | D13: =B13-C13 -> 0 | E13: =IFERROR(D13/B13,0) -> 0 | F13: =SUMIFS(Transactions!$F$3:$F$102,Transactions!$G$3:$G$102,A13) -> 0 | G13: =IFERROR((B13-B12)/B12,0) -> 0
A14: =A13+1 -> 2032 | B14: =SUMIFS(Transactions!$E$3:$E$102,Transactions!$B$3:$B$102,"Income",Transactions!$G$3:$G$102,A14) -> 0 | C14: =SUMIFS(Transactions!$E$3:$E$102,Transactions!$B$3:$B$102,"Expense",Transactions!$G$3:$G$102,A14) -> 0 | D14: =B14-C14 -> 0 | E14: =IFERROR(D14/B14,0) -> 0 | F14: =SUMIFS(Transactions!$F$3:$F$102,Transactions!$G$3:$G$102,A14) -> 0 | G14: =IFERROR((B14-B13)/B13,0) -> 0
A15: =A14+1 -> 2033 | B15: =SUMIFS(Transactions!$E$3:$E$102,Transactions!$B$3:$B$102,"Income",Transactions!$G$3:$G$102,A15) -> 0 | C15: =SUMIFS(Transactions!$E$3:$E$102,Transactions!$B$3:$B$102,"Expense",Transactions!$G$3:$G$102,A15) -> 0 | D15: =B15-C15 -> 0 | E15: =IFERROR(D15/B15,0) -> 0 | F15: =SUMIFS(Transactions!$F$3:$F$102,Transactions!$G$3:$G$102,A15) -> 0 | G15: =IFERROR((B15-B14)/B14,0) -> 0

Sheet Tax Summary
A1: {{CLIENT_NAME}} — Tax Summary
A2: {{NICHE}} — figures in {{CURRENCY}}
A3: Year | B3: 2026
A5: Month | B5: Tax Collected
A6: Jan | B6: =SUMIFS(Transactions!$F$3:$F$102,Transactions!$G$3:$G$102,$B$3,Transactions!$H$3:$H$102,1) -> 0
A7: Feb | B7: =SUMIFS(Transactions!$F$3:$F$102,Transactions!$G$3:$G$102,$B$3,Transactions!$H$3:$H$102,2) -> 0
A8: Mar | B8: =SUMIFS(Transactions!$F$3:$F$102,Transactions!$G$3:$G$102,$B$3,Transactions!$H$3:$H$102,3) -> 0
A9: Apr | B9: =SUMIFS(Transactions!$F$3:$F$102,Transactions!$G$3:$G$102,$B$3,Transactions!$H$3:$H$102,4) -> 0
A10: May | B10: =SUMIFS(Transactions!$F$3:$F$102,Transactions!$G$3:$G$102,$B$3,Transactions!$H$3:$H$102,5) -> 0
A11: Jun | B11: =SUMIFS(Transactions!$F$3:$F$102,Transactions!$G$3:$G$102,$B$3,Transactions!$H$3:$H$102,6) -> 0
A12: Jul | B12: =SUMIFS(Transactions!$F$3:$F$102,Transactions!$G$3:$G$102,$B$3,Transactions!$H$3:$H$102,7) -> 0
A13: Aug | B13: =SUMIFS(Transactions!$F$3:$F$102,Transactions!$G$3:$G$102,$B$3,Transactions!$H$3:$H$102,8) -> 0
A14: Sep | B14: =SUMIFS(Transactions!$F$3:$F$102,Transactions!$G$3:$G$102,$B$3,Transactions!$H$3:$H$102,9) -> 0
A15: Oct | B15: =SUMIFS(Transactions!$F$3:$F$102,Transactions!$G$3:$G$102,$B$3,Transactions!$H$3:$H$102,10) -> 0
A16: Nov | B16: =SUMIFS(Transactions!$F$3:$F$102,Transactions!$G$3:$G$102,$B$3,Transactions!$H$3:$H$102,11) -> 0
A17: Dec | B17: =SUMIFS(Transactions!$F$3:$F$102,Transactions!$G$3:$G$102,$B$3,Transactions!$H$3:$H$102,12) -> 0
A18: Annual Total | B18: =SUM(B6:B17) -> 0

Sheet Account Balance
A1: {{CLIENT_NAME}} — Account Balance
A2: {{NICHE}} — figures in {{CURRENCY}}
A3: Starting Balance ({{CURRENCY}}) | B3: Current Balance ({{CURRENCY}})
A4: =Setup!$B$7 -> 0 | B4: =Setup!$B$7+SUMIFS(Transactions!$E$3:$E$102,Transactions!$B$3:$B$102,"Income")-SUMIFS(Transactions!$E$3:$E$102,Transactions!$B$3:$B$102,"Expense") -> 0
A7: Bank Reconciliation
A8: Statement Date | B8: =TODAY() -> 46248
A9: Bank Statement Balance ({{CURRENCY}}) | B9: 0
A10: Book Balance as of Statement Date ({{CURRENCY}}) | B10: =Setup!$B$7+SUMIFS(Transactions!$E$3:$E$102,Transactions!$B$3:$B$102,"Income",Transactions!$A$3:$A$102,"<="&$B$8)-SUMIFS(Transactions!$E$3:$E$102,Transactions!$B$3:$B$102,"Expense",Transactions!$A$3:$A$102,"<="&$B$8) -> 0
A11: Difference ({{CURRENCY}}) | B11: =B9-B10 -> 0
A13: Ending Balance by Month | C13: Year | D13: 2026
A14: Month | B14: Ending Balance
A15: Jan | B15: =Setup!$B$7+SUMIFS(Transactions!$E$3:$E$102,Transactions!$B$3:$B$102,"Income",Transactions!$A$3:$A$102,"<="&(DATE($D$13,1+1,1)-1))-SUMIFS(Transactions!$E$3:$E$102,Transactions!$B$3:$B$102,"Expense",Transactions!$A$3:$A$102,"<="&(DATE($D$13,1+1,1)-1)) -> 0
A16: Feb | B16: =Setup!$B$7+SUMIFS(Transactions!$E$3:$E$102,Transactions!$B$3:$B$102,"Income",Transactions!$A$3:$A$102,"<="&(DATE($D$13,2+1,1)-1))-SUMIFS(Transactions!$E$3:$E$102,Transactions!$B$3:$B$102,"Expense",Transactions!$A$3:$A$102,"<="&(DATE($D$13,2+1,1)-1)) -> 0
A17: Mar | B17: =Setup!$B$7+SUMIFS(Transactions!$E$3:$E$102,Transactions!$B$3:$B$102,"Income",Transactions!$A$3:$A$102,"<="&(DATE($D$13,3+1,1)-1))-SUMIFS(Transactions!$E$3:$E$102,Transactions!$B$3:$B$102,"Expense",Transactions!$A$3:$A$102,"<="&(DATE($D$13,3+1,1)-1)) -> 0
A18: Apr | B18: =Setup!$B$7+SUMIFS(Transactions!$E$3:$E$102,Transactions!$B$3:$B$102,"Income",Transactions!$A$3:$A$102,"<="&(DATE($D$13,4+1,1)-1))-SUMIFS(Transactions!$E$3:$E$102,Transactions!$B$3:$B$102,"Expense",Transactions!$A$3:$A$102,"<="&(DATE($D$13,4+1,1)-1)) -> 0
A19: May | B19: =Setup!$B$7+SUMIFS(Transactions!$E$3:$E$102,Transactions!$B$3:$B$102,"Income",Transactions!$A$3:$A$102,"<="&(DATE($D$13,5+1,1)-1))-SUMIFS(Transactions!$E$3:$E$102,Transactions!$B$3:$B$102,"Expense",Transactions!$A$3:$A$102,"<="&(DATE($D$13,5+1,1)-1)) -> 0
A20: Jun | B20: =Setup!$B$7+SUMIFS(Transactions!$E$3:$E$102,Transactions!$B$3:$B$102,"Income",Transactions!$A$3:$A$102,"<="&(DATE($D$13,6+1,1)-1))-SUMIFS(Transactions!$E$3:$E$102,Transactions!$B$3:$B$102,"Expense",Transactions!$A$3:$A$102,"<="&(DATE($D$13,6+1,1)-1)) -> 0
A21: Jul | B21: =Setup!$B$7+SUMIFS(Transactions!$E$3:$E$102,Transactions!$B$3:$B$102,"Income",Transactions!$A$3:$A$102,"<="&(DATE($D$13,7+1,1)-1))-SUMIFS(Transactions!$E$3:$E$102,Transactions!$B$3:$B$102,"Expense",Transactions!$A$3:$A$102,"<="&(DATE($D$13,7+1,1)-1)) -> 0
A22: Aug | B22: =Setup!$B$7+SUMIFS(Transactions!$E$3:$E$102,Transactions!$B$3:$B$102,"Income",Transactions!$A$3:$A$102,"<="&(DATE($D$13,8+1,1)-1))-SUMIFS(Transactions!$E$3:$E$102,Transactions!$B$3:$B$102,"Expense",Transactions!$A$3:$A$102,"<="&(DATE($D$13,8+1,1)-1)) -> 0
A23: Sep | B23: =Setup!$B$7+SUMIFS(Transactions!$E$3:$E$102,Transactions!$B$3:$B$102,"Income",Transactions!$A$3:$A$102,"<="&(DATE($D$13,9+1,1)-1))-SUMIFS(Transactions!$E$3:$E$102,Transactions!$B$3:$B$102,"Expense",Transactions!$A$3:$A$102,"<="&(DATE($D$13,9+1,1)-1)) -> 0
A24: Oct | B24: =Setup!$B$7+SUMIFS(Transactions!$E$3:$E$102,Transactions!$B$3:$B$102,"Income",Transactions!$A$3:$A$102,"<="&(DATE($D$13,10+1,1)-1))-SUMIFS(Transactions!$E$3:$E$102,Transactions!$B$3:$B$102,"Expense",Transactions!$A$3:$A$102,"<="&(DATE($D$13,10+1,1)-1)) -> 0
A25: Nov | B25: =Setup!$B$7+SUMIFS(Transactions!$E$3:$E$102,Transactions!$B$3:$B$102,"Income",Transactions!$A$3:$A$102,"<="&(DATE($D$13,11+1,1)-1))-SUMIFS(Transactions!$E$3:$E$102,Transactions!$B$3:$B$102,"Expense",Transactions!$A$3:$A$102,"<="&(DATE($D$13,11+1,1)-1)) -> 0
A26: Dec | B26: =Setup!$B$7+SUMIFS(Transactions!$E$3:$E$102,Transactions!$B$3:$B$102,"Income",Transactions!$A$3:$A$102,"<="&(DATE($D$13,12+1,1)-1))-SUMIFS(Transactions!$E$3:$E$102,Transactions!$B$3:$B$102,"Expense",Transactions!$A$3:$A$102,"<="&(DATE($D$13,12+1,1)-1)) -> 0

Sheet Category Trends
A1: {{CLIENT_NAME}} — Category Trends
A2: {{NICHE}} — 12-month trend by category, figures in {{CURRENCY}}
A3: Year | B3: 2026
A5: Category | B5: Type | C5: Jan | D5: Feb | E5: Mar | F5: Apr | G5: May | H5: Jun | I5: Jul | J5: Aug | K5: Sep | L5: Oct | M5: Nov | N5: Dec
A6: Sales Revenue | B6: Income | C6: =SUMIFS(Transactions!$E$3:$E$102,Transactions!$B$3:$B$102,"Income",Transactions!$C$3:$C$102,"Sales Revenue",Transactions!$G$3:$G$102,$B$3,Transactions!$H$3:$H$102,1) -> 0 | D6: =SUMIFS(Transactions!$E$3:$E$102,Transactions!$B$3:$B$102,"Income",Transactions!$C$3:$C$102,"Sales Revenue",Transactions!$G$3:$G$102,$B$3,Transactions!$H$3:$H$102,2) -> 0 | E6: =SUMIFS(Transactions!$E$3:$E$102,Transactions!$B$3:$B$102,"Income",Transactions!$C$3:$C$102,"Sales Revenue",Transactions!$G$3:$G$102,$B$3,Transactions!$H$3:$H$102,3) -> 0 | F6: =SUMIFS(Transactions!$E$3:$E$102,Transactions!$B$3:$B$102,"Income",Transactions!$C$3:$C$102,"Sales Revenue",Transactions!$G$3:$G$102,$B$3,Transactions!$H$3:$H$102,4) -> 0 | G6: =SUMIFS(Transactions!$E$3:$E$102,Transactions!$B$3:$B$102,"Income",Transactions!$C$3:$C$102,"Sales Revenue",Transactions!$G$3:$G$102,$B$3,Transactions!$H$3:$H$102,5) -> 0 | H6: =SUMIFS(Transactions!$E$3:$E$102,Transactions!$B$3:$B$102,"Income",Transactions!$C$3:$C$102,"Sales Revenue",Transactions!$G$3:$G$102,$B$3,Transactions!$H$3:$H$102,6) -> 0 | I6: =SUMIFS(Transactions!$E$3:$E$102,Transactions!$B$3:$B$102,"Income",Transactions!$C$3:$C$102,"Sales Revenue",Transactions!$G$3:$G$102,$B$3,Transactions!$H$3:$H$102,7) -> 0 | J6: =SUMIFS(Transactions!$E$3:$E$102,Transactions!$B$3:$B$102,"Income",Transactions!$C$3:$C$102,"Sales Revenue",Transactions!$G$3:$G$102,$B$3,Transactions!$H$3:$H$102,8) -> 0 | K6: =SUMIFS(Transactions!$E$3:$E$102,Transactions!$B$3:$B$102,"Income",Transactions!$C$3:$C$102,"Sales Revenue",Transactions!$G$3:$G$102,$B$3,Transactions!$H$3:$H$102,9) -> 0 | L6: =SUMIFS(Transactions!$E$3:$E$102,Transactions!$B$3:$B$102,"Income",Transactions!$C$3:$C$102,"Sales Revenue",Transactions!$G$3:$G$102,$B$3,Transactions!$H$3:$H$102,10) -> 0 | M6: =SUMIFS(Transactions!$E$3:$E$102,Transactions!$B$3:$B$102,"Income",Transactions!$C$3:$C$102,"Sales Revenue",Transactions!$G$3:$G$102,$B$3,Transactions!$H$3:$H$102,11) -> 0 | N6: =SUMIFS(Transactions!$E$3:$E$102,Transactions!$B$3:$B$102,"Income",Transactions!$C$3:$C$102,"Sales Revenue",Transactions!$G$3:$G$102,$B$3,Transactions!$H$3:$H$102,12) -> 0
A7: Shipping Income | B7: Income | C7: =SUMIFS(Transactions!$E$3:$E$102,Transactions!$B$3:$B$102,"Income",Transactions!$C$3:$C$102,"Shipping Income",Transactions!$G$3:$G$102,$B$3,Transactions!$H$3:$H$102,1) -> 0 | D7: =SUMIFS(Transactions!$E$3:$E$102,Transactions!$B$3:$B$102,"Income",Transactions!$C$3:$C$102,"Shipping Income",Transactions!$G$3:$G$102,$B$3,Transactions!$H$3:$H$102,2) -> 0 | E7: =SUMIFS(Transactions!$E$3:$E$102,Transactions!$B$3:$B$102,"Income",Transactions!$C$3:$C$102,"Shipping Income",Transactions!$G$3:$G$102,$B$3,Transactions!$H$3:$H$102,3) -> 0 | F7: =SUMIFS(Transactions!$E$3:$E$102,Transactions!$B$3:$B$102,"Income",Transactions!$C$3:$C$102,"Shipping Income",Transactions!$G$3:$G$102,$B$3,Transactions!$H$3:$H$102,4) -> 0 | G7: =SUMIFS(Transactions!$E$3:$E$102,Transactions!$B$3:$B$102,"Income",Transactions!$C$3:$C$102,"Shipping Income",Transactions!$G$3:$G$102,$B$3,Transactions!$H$3:$H$102,5) -> 0 | H7: =SUMIFS(Transactions!$E$3:$E$102,Transactions!$B$3:$B$102,"Income",Transactions!$C$3:$C$102,"Shipping Income",Transactions!$G$3:$G$102,$B$3,Transactions!$H$3:$H$102,6) -> 0 | I7: =SUMIFS(Transactions!$E$3:$E$102,Transactions!$B$3:$B$102,"Income",Transactions!$C$3:$C$102,"Shipping Income",Transactions!$G$3:$G$102,$B$3,Transactions!$H$3:$H$102,7) -> 0 | J7: =SUMIFS(Transactions!$E$3:$E$102,Transactions!$B$3:$B$102,"Income",Transactions!$C$3:$C$102,"Shipping Income",Transactions!$G$3:$G$102,$B$3,Transactions!$H$3:$H$102,8) -> 0 | K7: =SUMIFS(Transactions!$E$3:$E$102,Transactions!$B$3:$B$102,"Income",Transactions!$C$3:$C$102,"Shipping Income",Transactions!$G$3:$G$102,$B$3,Transactions!$H$3:$H$102,9) -> 0 | L7: =SUMIFS(Transactions!$E$3:$E$102,Transactions!$B$3:$B$102,"Income",Transactions!$C$3:$C$102,"Shipping Income",Transactions!$G$3:$G$102,$B$3,Transactions!$H$3:$H$102,10) -> 0 | M7: =SUMIFS(Transactions!$E$3:$E$102,Transactions!$B$3:$B$102,"Income",Transactions!$C$3:$C$102,"Shipping Income",Transactions!$G$3:$G$102,$B$3,Transactions!$H$3:$H$102,11) -> 0 | N7: =SUMIFS(Transactions!$E$3:$E$102,Transactions!$B$3:$B$102,"Income",Transactions!$C$3:$C$102,"Shipping Income",Transactions!$G$3:$G$102,$B$3,Transactions!$H$3:$H$102,12) -> 0
A8: Custom Orders | B8: Income | C8: =SUMIFS(Transactions!$E$3:$E$102,Transactions!$B$3:$B$102,"Income",Transactions!$C$3:$C$102,"Custom Orders",Transactions!$G$3:$G$102,$B$3,Transactions!$H$3:$H$102,1) -> 0 | D8: =SUMIFS(Transactions!$E$3:$E$102,Transactions!$B$3:$B$102,"Income",Transactions!$C$3:$C$102,"Custom Orders",Transactions!$G$3:$G$102,$B$3,Transactions!$H$3:$H$102,2) -> 0 | E8: =SUMIFS(Transactions!$E$3:$E$102,Transactions!$B$3:$B$102,"Income",Transactions!$C$3:$C$102,"Custom Orders",Transactions!$G$3:$G$102,$B$3,Transactions!$H$3:$H$102,3) -> 0 | F8: =SUMIFS(Transactions!$E$3:$E$102,Transactions!$B$3:$B$102,"Income",Transactions!$C$3:$C$102,"Custom Orders",Transactions!$G$3:$G$102,$B$3,Transactions!$H$3:$H$102,4) -> 0 | G8: =SUMIFS(Transactions!$E$3:$E$102,Transactions!$B$3:$B$102,"Income",Transactions!$C$3:$C$102,"Custom Orders",Transactions!$G$3:$G$102,$B$3,Transactions!$H$3:$H$102,5) -> 0 | H8: =SUMIFS(Transactions!$E$3:$E$102,Transactions!$B$3:$B$102,"Income",Transactions!$C$3:$C$102,"Custom Orders",Transactions!$G$3:$G$102,$B$3,Transactions!$H$3:$H$102,6) -> 0 | I8: =SUMIFS(Transactions!$E$3:$E$102,Transactions!$B$3:$B$102,"Income",Transactions!$C$3:$C$102,"Custom Orders",Transactions!$G$3:$G$102,$B$3,Transactions!$H$3:$H$102,7) -> 0 | J8: =SUMIFS(Transactions!$E$3:$E$102,Transactions!$B$3:$B$102,"Income",Transactions!$C$3:$C$102,"Custom Orders",Transactions!$G$3:$G$102,$B$3,Transactions!$H$3:$H$102,8) -> 0 | K8: =SUMIFS(Transactions!$E$3:$E$102,Transactions!$B$3:$B$102,"Income",Transactions!$C$3:$C$102,"Custom Orders",Transactions!$G$3:$G$102,$B$3,Transactions!$H$3:$H$102,9) -> 0 | L8: =SUMIFS(Transactions!$E$3:$E$102,Transactions!$B$3:$B$102,"Income",Transactions!$C$3:$C$102,"Custom Orders",Transactions!$G$3:$G$102,$B$3,Transactions!$H$3:$H$102,10) -> 0 | M8: =SUMIFS(Transactions!$E$3:$E$102,Transactions!$B$3:$B$102,"Income",Transactions!$C$3:$C$102,"Custom Orders",Transactions!$G$3:$G$102,$B$3,Transactions!$H$3:$H$102,11) -> 0 | N8: =SUMIFS(Transactions!$E$3:$E$102,Transactions!$B$3:$B$102,"Income",Transactions!$C$3:$C$102,"Custom Orders",Transactions!$G$3:$G$102,$B$3,Transactions!$H$3:$H$102,12) -> 0
A9: Wholesale | B9: Income | C9: =SUMIFS(Transactions!$E$3:$E$102,Transactions!$B$3:$B$102,"Income",Transactions!$C$3:$C$102,"Wholesale",Transactions!$G$3:$G$102,$B$3,Transactions!$H$3:$H$102,1) -> 0 | D9: =SUMIFS(Transactions!$E$3:$E$102,Transactions!$B$3:$B$102,"Income",Transactions!$C$3:$C$102,"Wholesale",Transactions!$G$3:$G$102,$B$3,Transactions!$H$3:$H$102,2) -> 0 | E9: =SUMIFS(Transactions!$E$3:$E$102,Transactions!$B$3:$B$102,"Income",Transactions!$C$3:$C$102,"Wholesale",Transactions!$G$3:$G$102,$B$3,Transactions!$H$3:$H$102,3) -> 0 | F9: =SUMIFS(Transactions!$E$3:$E$102,Transactions!$B$3:$B$102,"Income",Transactions!$C$3:$C$102,"Wholesale",Transactions!$G$3:$G$102,$B$3,Transactions!$H$3:$H$102,4) -> 0 | G9: =SUMIFS(Transactions!$E$3:$E$102,Transactions!$B$3:$B$102,"Income",Transactions!$C$3:$C$102,"Wholesale",Transactions!$G$3:$G$102,$B$3,Transactions!$H$3:$H$102,5) -> 0 | H9: =SUMIFS(Transactions!$E$3:$E$102,Transactions!$B$3:$B$102,"Income",Transactions!$C$3:$C$102,"Wholesale",Transactions!$G$3:$G$102,$B$3,Transactions!$H$3:$H$102,6) -> 0 | I9: =SUMIFS(Transactions!$E$3:$E$102,Transactions!$B$3:$B$102,"Income",Transactions!$C$3:$C$102,"Wholesale",Transactions!$G$3:$G$102,$B$3,Transactions!$H$3:$H$102,7) -> 0 | J9: =SUMIFS(Transactions!$E$3:$E$102,Transactions!$B$3:$B$102,"Income",Transactions!$C$3:$C$102,"Wholesale",Transactions!$G$3:$G$102,$B$3,Transactions!$H$3:$H$102,8) -> 0 | K9: =SUMIFS(Transactions!$E$3:$E$102,Transactions!$B$3:$B$102,"Income",Transactions!$C$3:$C$102,"Wholesale",Transactions!$G$3:$G$102,$B$3,Transactions!$H$3:$H$102,9) -> 0 | L9: =SUMIFS(Transactions!$E$3:$E$102,Transactions!$B$3:$B$102,"Income",Transactions!$C$3:$C$102,"Wholesale",Transactions!$G$3:$G$102,$B$3,Transactions!$H$3:$H$102,10) -> 0 | M9: =SUMIFS(Transactions!$E$3:$E$102,Transactions!$B$3:$B$102,"Income",Transactions!$C$3:$C$102,"Wholesale",Transactions!$G$3:$G$102,$B$3,Transactions!$H$3:$H$102,11) -> 0 | N9: =SUMIFS(Transactions!$E$3:$E$102,Transactions!$B$3:$B$102,"Income",Transactions!$C$3:$C$102,"Wholesale",Transactions!$G$3:$G$102,$B$3,Transactions!$H$3:$H$102,12) -> 0
A10: Other Income | B10: Income | C10: =SUMIFS(Transactions!$E$3:$E$102,Transactions!$B$3:$B$102,"Income",Transactions!$C$3:$C$102,"Other Income",Transactions!$G$3:$G$102,$B$3,Transactions!$H$3:$H$102,1) -> 0 | D10: =SUMIFS(Transactions!$E$3:$E$102,Transactions!$B$3:$B$102,"Income",Transactions!$C$3:$C$102,"Other Income",Transactions!$G$3:$G$102,$B$3,Transactions!$H$3:$H$102,2) -> 0 | E10: =SUMIFS(Transactions!$E$3:$E$102,Transactions!$B$3:$B$102,"Income",Transactions!$C$3:$C$102,"Other Income",Transactions!$G$3:$G$102,$B$3,Transactions!$H$3:$H$102,3) -> 0 | F10: =SUMIFS(Transactions!$E$3:$E$102,Transactions!$B$3:$B$102,"Income",Transactions!$C$3:$C$102,"Other Income",Transactions!$G$3:$G$102,$B$3,Transactions!$H$3:$H$102,4) -> 0 | G10: =SUMIFS(Transactions!$E$3:$E$102,Transactions!$B$3:$B$102,"Income",Transactions!$C$3:$C$102,"Other Income",Transactions!$G$3:$G$102,$B$3,Transactions!$H$3:$H$102,5) -> 0 | H10: =SUMIFS(Transactions!$E$3:$E$102,Transactions!$B$3:$B$102,"Income",Transactions!$C$3:$C$102,"Other Income",Transactions!$G$3:$G$102,$B$3,Transactions!$H$3:$H$102,6) -> 0 | I10: =SUMIFS(Transactions!$E$3:$E$102,Transactions!$B$3:$B$102,"Income",Transactions!$C$3:$C$102,"Other Income",Transactions!$G$3:$G$102,$B$3,Transactions!$H$3:$H$102,7) -> 0 | J10: =SUMIFS(Transactions!$E$3:$E$102,Transactions!$B$3:$B$102,"Income",Transactions!$C$3:$C$102,"Other Income",Transactions!$G$3:$G$102,$B$3,Transactions!$H$3:$H$102,8) -> 0 | K10: =SUMIFS(Transactions!$E$3:$E$102,Transactions!$B$3:$B$102,"Income",Transactions!$C$3:$C$102,"Other Income",Transactions!$G$3:$G$102,$B$3,Transactions!$H$3:$H$102,9) -> 0 | L10: =SUMIFS(Transactions!$E$3:$E$102,Transactions!$B$3:$B$102,"Income",Transactions!$C$3:$C$102,"Other Income",Transactions!$G$3:$G$102,$B$3,Transactions!$H$3:$H$102,10) -> 0 | M10: =SUMIFS(Transactions!$E$3:$E$102,Transactions!$B$3:$B$102,"Income",Transactions!$C$3:$C$102,"Other Income",Transactions!$G$3:$G$102,$B$3,Transactions!$H$3:$H$102,11) -> 0 | N10: =SUMIFS(Transactions!$E$3:$E$102,Transactions!$B$3:$B$102,"Income",Transactions!$C$3:$C$102,"Other Income",Transactions!$G$3:$G$102,$B$3,Transactions!$H$3:$H$102,12) -> 0
A11: Cost of Goods | B11: Expense | C11: =SUMIFS(Transactions!$E$3:$E$102,Transactions!$B$3:$B$102,"Expense",Transactions!$C$3:$C$102,"Cost of Goods",Transactions!$G$3:$G$102,$B$3,Transactions!$H$3:$H$102,1) -> 0 | D11: =SUMIFS(Transactions!$E$3:$E$102,Transactions!$B$3:$B$102,"Expense",Transactions!$C$3:$C$102,"Cost of Goods",Transactions!$G$3:$G$102,$B$3,Transactions!$H$3:$H$102,2) -> 0 | E11: =SUMIFS(Transactions!$E$3:$E$102,Transactions!$B$3:$B$102,"Expense",Transactions!$C$3:$C$102,"Cost of Goods",Transactions!$G$3:$G$102,$B$3,Transactions!$H$3:$H$102,3) -> 0 | F11: =SUMIFS(Transactions!$E$3:$E$102,Transactions!$B$3:$B$102,"Expense",Transactions!$C$3:$C$102,"Cost of Goods",Transactions!$G$3:$G$102,$B$3,Transactions!$H$3:$H$102,4) -> 0 | G11: =SUMIFS(Transactions!$E$3:$E$102,Transactions!$B$3:$B$102,"Expense",Transactions!$C$3:$C$102,"Cost of Goods",Transactions!$G$3:$G$102,$B$3,Transactions!$H$3:$H$102,5) -> 0 | H11: =SUMIFS(Transactions!$E$3:$E$102,Transactions!$B$3:$B$102,"Expense",Transactions!$C$3:$C$102,"Cost of Goods",Transactions!$G$3:$G$102,$B$3,Transactions!$H$3:$H$102,6) -> 0 | I11: =SUMIFS(Transactions!$E$3:$E$102,Transactions!$B$3:$B$102,"Expense",Transactions!$C$3:$C$102,"Cost of Goods",Transactions!$G$3:$G$102,$B$3,Transactions!$H$3:$H$102,7) -> 0 | J11: =SUMIFS(Transactions!$E$3:$E$102,Transactions!$B$3:$B$102,"Expense",Transactions!$C$3:$C$102,"Cost of Goods",Transactions!$G$3:$G$102,$B$3,Transactions!$H$3:$H$102,8) -> 0 | K11: =SUMIFS(Transactions!$E$3:$E$102,Transactions!$B$3:$B$102,"Expense",Transactions!$C$3:$C$102,"Cost of Goods",Transactions!$G$3:$G$102,$B$3,Transactions!$H$3:$H$102,9) -> 0 | L11: =SUMIFS(Transactions!$E$3:$E$102,Transactions!$B$3:$B$102,"Expense",Transactions!$C$3:$C$102,"Cost of Goods",Transactions!$G$3:$G$102,$B$3,Transactions!$H$3:$H$102,10) -> 0 | M11: =SUMIFS(Transactions!$E$3:$E$102,Transactions!$B$3:$B$102,"Expense",Transactions!$C$3:$C$102,"Cost of Goods",Transactions!$G$3:$G$102,$B$3,Transactions!$H$3:$H$102,11) -> 0 | N11: =SUMIFS(Transactions!$E$3:$E$102,Transactions!$B$3:$B$102,"Expense",Transactions!$C$3:$C$102,"Cost of Goods",Transactions!$G$3:$G$102,$B$3,Transactions!$H$3:$H$102,12) -> 0
A12: Shipping Costs | B12: Expense | C12: =SUMIFS(Transactions!$E$3:$E$102,Transactions!$B$3:$B$102,"Expense",Transactions!$C$3:$C$102,"Shipping Costs",Transactions!$G$3:$G$102,$B$3,Transactions!$H$3:$H$102,1) -> 0 | D12: =SUMIFS(Transactions!$E$3:$E$102,Transactions!$B$3:$B$102,"Expense",Transactions!$C$3:$C$102,"Shipping Costs",Transactions!$G$3:$G$102,$B$3,Transactions!$H$3:$H$102,2) -> 0 | E12: =SUMIFS(Transactions!$E$3:$E$102,Transactions!$B$3:$B$102,"Expense",Transactions!$C$3:$C$102,"Shipping Costs",Transactions!$G$3:$G$102,$B$3,Transactions!$H$3:$H$102,3) -> 0 | F12: =SUMIFS(Transactions!$E$3:$E$102,Transactions!$B$3:$B$102,"Expense",Transactions!$C$3:$C$102,"Shipping Costs",Transactions!$G$3:$G$102,$B$3,Transactions!$H$3:$H$102,4) -> 0 | G12: =SUMIFS(Transactions!$E$3:$E$102,Transactions!$B$3:$B$102,"Expense",Transactions!$C$3:$C$102,"Shipping Costs",Transactions!$G$3:$G$102,$B$3,Transactions!$H$3:$H$102,5) -> 0 | H12: =SUMIFS(Transactions!$E$3:$E$102,Transactions!$B$3:$B$102,"Expense",Transactions!$C$3:$C$102,"Shipping Costs",Transactions!$G$3:$G$102,$B$3,Transactions!$H$3:$H$102,6) -> 0 | I12: =SUMIFS(Transactions!$E$3:$E$102,Transactions!$B$3:$B$102,"Expense",Transactions!$C$3:$C$102,"Shipping Costs",Transactions!$G$3:$G$102,$B$3,Transactions!$H$3:$H$102,7) -> 0 | J12: =SUMIFS(Transactions!$E$3:$E$102,Transactions!$B$3:$B$102,"Expense",Transactions!$C$3:$C$102,"Shipping Costs",Transactions!$G$3:$G$102,$B$3,Transactions!$H$3:$H$102,8) -> 0 | K12: =SUMIFS(Transactions!$E$3:$E$102,Transactions!$B$3:$B$102,"Expense",Transactions!$C$3:$C$102,"Shipping Costs",Transactions!$G$3:$G$102,$B$3,Transactions!$H$3:$H$102,9) -> 0 | L12: =SUMIFS(Transactions!$E$3:$E$102,Transactions!$B$3:$B$102,"Expense",Transactions!$C$3:$C$102,"Shipping Costs",Transactions!$G$3:$G$102,$B$3,Transactions!$H$3:$H$102,10) -> 0 | M12: =SUMIFS(Transactions!$E$3:$E$102,Transactions!$B$3:$B$102,"Expense",Transactions!$C$3:$C$102,"Shipping Costs",Transactions!$G$3:$G$102,$B$3,Transactions!$H$3:$H$102,11) -> 0 | N12: =SUMIFS(Transactions!$E$3:$E$102,Transactions!$B$3:$B$102,"Expense",Transactions!$C$3:$C$102,"Shipping Costs",Transactions!$G$3:$G$102,$B$3,Transactions!$H$3:$H$102,12) -> 0
A13: Marketing | B13: Expense | C13: =SUMIFS(Transactions!$E$3:$E$102,Transactions!$B$3:$B$102,"Expense",Transactions!$C$3:$C$102,"Marketing",Transactions!$G$3:$G$102,$B$3,Transactions!$H$3:$H$102,1) -> 0 | D13: =SUMIFS(Transactions!$E$3:$E$102,Transactions!$B$3:$B$102,"Expense",Transactions!$C$3:$C$102,"Marketing",Transactions!$G$3:$G$102,$B$3,Transactions!$H$3:$H$102,2) -> 0 | E13: =SUMIFS(Transactions!$E$3:$E$102,Transactions!$B$3:$B$102,"Expense",Transactions!$C$3:$C$102,"Marketing",Transactions!$G$3:$G$102,$B$3,Transactions!$H$3:$H$102,3) -> 0 | F13: =SUMIFS(Transactions!$E$3:$E$102,Transactions!$B$3:$B$102,"Expense",Transactions!$C$3:$C$102,"Marketing",Transactions!$G$3:$G$102,$B$3,Transactions!$H$3:$H$102,4) -> 0 | G13: =SUMIFS(Transactions!$E$3:$E$102,Transactions!$B$3:$B$102,"Expense",Transactions!$C$3:$C$102,"Marketing",Transactions!$G$3:$G$102,$B$3,Transactions!$H$3:$H$102,5) -> 0 | H13: =SUMIFS(Transactions!$E$3:$E$102,Transactions!$B$3:$B$102,"Expense",Transactions!$C$3:$C$102,"Marketing",Transactions!$G$3:$G$102,$B$3,Transactions!$H$3:$H$102,6) -> 0 | I13: =SUMIFS(Transactions!$E$3:$E$102,Transactions!$B$3:$B$102,"Expense",Transactions!$C$3:$C$102,"Marketing",Transactions!$G$3:$G$102,$B$3,Transactions!$H$3:$H$102,7) -> 0 | J13: =SUMIFS(Transactions!$E$3:$E$102,Transactions!$B$3:$B$102,"Expense",Transactions!$C$3:$C$102,"Marketing",Transactions!$G$3:$G$102,$B$3,Transactions!$H$3:$H$102,8) -> 0 | K13: =SUMIFS(Transactions!$E$3:$E$102,Transactions!$B$3:$B$102,"Expense",Transactions!$C$3:$C$102,"Marketing",Transactions!$G$3:$G$102,$B$3,Transactions!$H$3:$H$102,9) -> 0 | L13: =SUMIFS(Transactions!$E$3:$E$102,Transactions!$B$3:$B$102,"Expense",Transactions!$C$3:$C$102,"Marketing",Transactions!$G$3:$G$102,$B$3,Transactions!$H$3:$H$102,10) -> 0 | M13: =SUMIFS(Transactions!$E$3:$E$102,Transactions!$B$3:$B$102,"Expense",Transactions!$C$3:$C$102,"Marketing",Transactions!$G$3:$G$102,$B$3,Transactions!$H$3:$H$102,11) -> 0 | N13: =SUMIFS(Transactions!$E$3:$E$102,Transactions!$B$3:$B$102,"Expense",Transactions!$C$3:$C$102,"Marketing",Transactions!$G$3:$G$102,$B$3,Transactions!$H$3:$H$102,12) -> 0
A14: Software & Tools | B14: Expense | C14: =SUMIFS(Transactions!$E$3:$E$102,Transactions!$B$3:$B$102,"Expense",Transactions!$C$3:$C$102,"Software & Tools",Transactions!$G$3:$G$102,$B$3,Transactions!$H$3:$H$102,1) -> 0 | D14: =SUMIFS(Transactions!$E$3:$E$102,Transactions!$B$3:$B$102,"Expense",Transactions!$C$3:$C$102,"Software & Tools",Transactions!$G$3:$G$102,$B$3,Transactions!$H$3:$H$102,2) -> 0 | E14: =SUMIFS(Transactions!$E$3:$E$102,Transactions!$B$3:$B$102,"Expense",Transactions!$C$3:$C$102,"Software & Tools",Transactions!$G$3:$G$102,$B$3,Transactions!$H$3:$H$102,3) -> 0 | F14: =SUMIFS(Transactions!$E$3:$E$102,Transactions!$B$3:$B$102,"Expense",Transactions!$C$3:$C$102,"Software & Tools",Transactions!$G$3:$G$102,$B$3,Transactions!$H$3:$H$102,4) -> 0 | G14: =SUMIFS(Transactions!$E$3:$E$102,Transactions!$B$3:$B$102,"Expense",Transactions!$C$3:$C$102,"Software & Tools",Transactions!$G$3:$G$102,$B$3,Transactions!$H$3:$H$102,5) -> 0 | H14: =SUMIFS(Transactions!$E$3:$E$102,Transactions!$B$3:$B$102,"Expense",Transactions!$C$3:$C$102,"Software & Tools",Transactions!$G$3:$G$102,$B$3,Transactions!$H$3:$H$102,6) -> 0 | I14: =SUMIFS(Transactions!$E$3:$E$102,Transactions!$B$3:$B$102,"Expense",Transactions!$C$3:$C$102,"Software & Tools",Transactions!$G$3:$G$102,$B$3,Transactions!$H$3:$H$102,7) -> 0 | J14: =SUMIFS(Transactions!$E$3:$E$102,Transactions!$B$3:$B$102,"Expense",Transactions!$C$3:$C$102,"Software & Tools",Transactions!$G$3:$G$102,$B$3,Transactions!$H$3:$H$102,8) -> 0 | K14: =SUMIFS(Transactions!$E$3:$E$102,Transactions!$B$3:$B$102,"Expense",Transactions!$C$3:$C$102,"Software & Tools",Transactions!$G$3:$G$102,$B$3,Transactions!$H$3:$H$102,9) -> 0 | L14: =SUMIFS(Transactions!$E$3:$E$102,Transactions!$B$3:$B$102,"Expense",Transactions!$C$3:$C$102,"Software & Tools",Transactions!$G$3:$G$102,$B$3,Transactions!$H$3:$H$102,10) -> 0 | M14: =SUMIFS(Transactions!$E$3:$E$102,Transactions!$B$3:$B$102,"Expense",Transactions!$C$3:$C$102,"Software & Tools",Transactions!$G$3:$G$102,$B$3,Transactions!$H$3:$H$102,11) -> 0 | N14: =SUMIFS(Transactions!$E$3:$E$102,Transactions!$B$3:$B$102,"Expense",Transactions!$C$3:$C$102,"Software & Tools",Transactions!$G$3:$G$102,$B$3,Transactions!$H$3:$H$102,12) -> 0
A15: Fees & Commissions | B15: Expense | C15: =SUMIFS(Transactions!$E$3:$E$102,Transactions!$B$3:$B$102,"Expense",Transactions!$C$3:$C$102,"Fees & Commissions",Transactions!$G$3:$G$102,$B$3,Transactions!$H$3:$H$102,1) -> 0 | D15: =SUMIFS(Transactions!$E$3:$E$102,Transactions!$B$3:$B$102,"Expense",Transactions!$C$3:$C$102,"Fees & Commissions",Transactions!$G$3:$G$102,$B$3,Transactions!$H$3:$H$102,2) -> 0 | E15: =SUMIFS(Transactions!$E$3:$E$102,Transactions!$B$3:$B$102,"Expense",Transactions!$C$3:$C$102,"Fees & Commissions",Transactions!$G$3:$G$102,$B$3,Transactions!$H$3:$H$102,3) -> 0 | F15: =SUMIFS(Transactions!$E$3:$E$102,Transactions!$B$3:$B$102,"Expense",Transactions!$C$3:$C$102,"Fees & Commissions",Transactions!$G$3:$G$102,$B$3,Transactions!$H$3:$H$102,4) -> 0 | G15: =SUMIFS(Transactions!$E$3:$E$102,Transactions!$B$3:$B$102,"Expense",Transactions!$C$3:$C$102,"Fees & Commissions",Transactions!$G$3:$G$102,$B$3,Transactions!$H$3:$H$102,5) -> 0 | H15: =SUMIFS(Transactions!$E$3:$E$102,Transactions!$B$3:$B$102,"Expense",Transactions!$C$3:$C$102,"Fees & Commissions",Transactions!$G$3:$G$102,$B$3,Transactions!$H$3:$H$102,6) -> 0 | I15: =SUMIFS(Transactions!$E$3:$E$102,Transactions!$B$3:$B$102,"Expense",Transactions!$C$3:$C$102,"Fees & Commissions",Transactions!$G$3:$G$102,$B$3,Transactions!$H$3:$H$102,7) -> 0 | J15: =SUMIFS(Transactions!$E$3:$E$102,Transactions!$B$3:$B$102,"Expense",Transactions!$C$3:$C$102,"Fees & Commissions",Transactions!$G$3:$G$102,$B$3,Transactions!$H$3:$H$102,8) -> 0 | K15: =SUMIFS(Transactions!$E$3:$E$102,Transactions!$B$3:$B$102,"Expense",Transactions!$C$3:$C$102,"Fees & Commissions",Transactions!$G$3:$G$102,$B$3,Transactions!$H$3:$H$102,9) -> 0 | L15: =SUMIFS(Transactions!$E$3:$E$102,Transactions!$B$3:$B$102,"Expense",Transactions!$C$3:$C$102,"Fees & Commissions",Transactions!$G$3:$G$102,$B$3,Transactions!$H$3:$H$102,10) -> 0 | M15: =SUMIFS(Transactions!$E$3:$E$102,Transactions!$B$3:$B$102,"Expense",Transactions!$C$3:$C$102,"Fees & Commissions",Transactions!$G$3:$G$102,$B$3,Transactions!$H$3:$H$102,11) -> 0 | N15: =SUMIFS(Transactions!$E$3:$E$102,Transactions!$B$3:$B$102,"Expense",Transactions!$C$3:$C$102,"Fees & Commissions",Transactions!$G$3:$G$102,$B$3,Transactions!$H$3:$H$102,12) -> 0
A16: Office Supplies | B16: Expense | C16: =SUMIFS(Transactions!$E$3:$E$102,Transactions!$B$3:$B$102,"Expense",Transactions!$C$3:$C$102,"Office Supplies",Transactions!$G$3:$G$102,$B$3,Transactions!$H$3:$H$102,1) -> 0 | D16: =SUMIFS(Transactions!$E$3:$E$102,Transactions!$B$3:$B$102,"Expense",Transactions!$C$3:$C$102,"Office Supplies",Transactions!$G$3:$G$102,$B$3,Transactions!$H$3:$H$102,2) -> 0 | E16: =SUMIFS(Transactions!$E$3:$E$102,Transactions!$B$3:$B$102,"Expense",Transactions!$C$3:$C$102,"Office Supplies",Transactions!$G$3:$G$102,$B$3,Transactions!$H$3:$H$102,3) -> 0 | F16: =SUMIFS(Transactions!$E$3:$E$102,Transactions!$B$3:$B$102,"Expense",Transactions!$C$3:$C$102,"Office Supplies",Transactions!$G$3:$G$102,$B$3,Transactions!$H$3:$H$102,4) -> 0 | G16: =SUMIFS(Transactions!$E$3:$E$102,Transactions!$B$3:$B$102,"Expense",Transactions!$C$3:$C$102,"Office Supplies",Transactions!$G$3:$G$102,$B$3,Transactions!$H$3:$H$102,5) -> 0 | H16: =SUMIFS(Transactions!$E$3:$E$102,Transactions!$B$3:$B$102,"Expense",Transactions!$C$3:$C$102,"Office Supplies",Transactions!$G$3:$G$102,$B$3,Transactions!$H$3:$H$102,6) -> 0 | I16: =SUMIFS(Transactions!$E$3:$E$102,Transactions!$B$3:$B$102,"Expense",Transactions!$C$3:$C$102,"Office Supplies",Transactions!$G$3:$G$102,$B$3,Transactions!$H$3:$H$102,7) -> 0 | J16: =SUMIFS(Transactions!$E$3:$E$102,Transactions!$B$3:$B$102,"Expense",Transactions!$C$3:$C$102,"Office Supplies",Transactions!$G$3:$G$102,$B$3,Transactions!$H$3:$H$102,8) -> 0 | K16: =SUMIFS(Transactions!$E$3:$E$102,Transactions!$B$3:$B$102,"Expense",Transactions!$C$3:$C$102,"Office Supplies",Transactions!$G$3:$G$102,$B$3,Transactions!$H$3:$H$102,9) -> 0 | L16: =SUMIFS(Transactions!$E$3:$E$102,Transactions!$B$3:$B$102,"Expense",Transactions!$C$3:$C$102,"Office Supplies",Transactions!$G$3:$G$102,$B$3,Transactions!$H$3:$H$102,10) -> 0 | M16: =SUMIFS(Transactions!$E$3:$E$102,Transactions!$B$3:$B$102,"Expense",Transactions!$C$3:$C$102,"Office Supplies",Transactions!$G$3:$G$102,$B$3,Transactions!$H$3:$H$102,11) -> 0 | N16: =SUMIFS(Transactions!$E$3:$E$102,Transactions!$B$3:$B$102,"Expense",Transactions!$C$3:$C$102,"Office Supplies",Transactions!$G$3:$G$102,$B$3,Transactions!$H$3:$H$102,12) -> 0
A17: Rent | B17: Expense | C17: =SUMIFS(Transactions!$E$3:$E$102,Transactions!$B$3:$B$102,"Expense",Transactions!$C$3:$C$102,"Rent",Transactions!$G$3:$G$102,$B$3,Transactions!$H$3:$H$102,1) -> 0 | D17: =SUMIFS(Transactions!$E$3:$E$102,Transactions!$B$3:$B$102,"Expense",Transactions!$C$3:$C$102,"Rent",Transactions!$G$3:$G$102,$B$3,Transactions!$H$3:$H$102,2) -> 0 | E17: =SUMIFS(Transactions!$E$3:$E$102,Transactions!$B$3:$B$102,"Expense",Transactions!$C$3:$C$102,"Rent",Transactions!$G$3:$G$102,$B$3,Transactions!$H$3:$H$102,3) -> 0 | F17: =SUMIFS(Transactions!$E$3:$E$102,Transactions!$B$3:$B$102,"Expense",Transactions!$C$3:$C$102,"Rent",Transactions!$G$3:$G$102,$B$3,Transactions!$H$3:$H$102,4) -> 0 | G17: =SUMIFS(Transactions!$E$3:$E$102,Transactions!$B$3:$B$102,"Expense",Transactions!$C$3:$C$102,"Rent",Transactions!$G$3:$G$102,$B$3,Transactions!$H$3:$H$102,5) -> 0 | H17: =SUMIFS(Transactions!$E$3:$E$102,Transactions!$B$3:$B$102,"Expense",Transactions!$C$3:$C$102,"Rent",Transactions!$G$3:$G$102,$B$3,Transactions!$H$3:$H$102,6) -> 0 | I17: =SUMIFS(Transactions!$E$3:$E$102,Transactions!$B$3:$B$102,"Expense",Transactions!$C$3:$C$102,"Rent",Transactions!$G$3:$G$102,$B$3,Transactions!$H$3:$H$102,7) -> 0 | J17: =SUMIFS(Transactions!$E$3:$E$102,Transactions!$B$3:$B$102,"Expense",Transactions!$C$3:$C$102,"Rent",Transactions!$G$3:$G$102,$B$3,Transactions!$H$3:$H$102,8) -> 0 | K17: =SUMIFS(Transactions!$E$3:$E$102,Transactions!$B$3:$B$102,"Expense",Transactions!$C$3:$C$102,"Rent",Transactions!$G$3:$G$102,$B$3,Transactions!$H$3:$H$102,9) -> 0 | L17: =SUMIFS(Transactions!$E$3:$E$102,Transactions!$B$3:$B$102,"Expense",Transactions!$C$3:$C$102,"Rent",Transactions!$G$3:$G$102,$B$3,Transactions!$H$3:$H$102,10) -> 0 | M17: =SUMIFS(Transactions!$E$3:$E$102,Transactions!$B$3:$B$102,"Expense",Transactions!$C$3:$C$102,"Rent",Transactions!$G$3:$G$102,$B$3,Transactions!$H$3:$H$102,11) -> 0 | N17: =SUMIFS(Transactions!$E$3:$E$102,Transactions!$B$3:$B$102,"Expense",Transactions!$C$3:$C$102,"Rent",Transactions!$G$3:$G$102,$B$3,Transactions!$H$3:$H$102,12) -> 0
